package com.luxoft.jva008.module04;

import static org.junit.Assert.assertFalse;

import java.util.*;

import org.junit.Test;

/*
 *  Why does the program (periodically) fail with ArrayIndexOutOfBoundException?
 *  What should you do to prevent this happening?
 *  An exception is not always thrown, you might need to run the program multiple times.
*/

public class SynchronizedListTutor {
	static boolean failed = false;
    static StringBuffer buf = new StringBuffer();
    static void log(String s) {
        buf.append(s + "\n");
    }
	
	static void err(String s) {
        buf.append("<span style='color:red'><b>"+s+"</b></span>\n");
        failed = true;
    }
	
	static String [] animals =
	    { "Cow", "Goose", "Cat", "Dog", "Elephant", "Rabbit", "Snake", "Chicken", "Horse", "Human" };
	List<String> randomAnimals = new ArrayList<>();
	List<String> syncAnimals = Collections.synchronizedList(randomAnimals);
	
	public String getRandomAnimal() {
		int index = (int)(Math.random() * animals.length);
 	    return animals[index];
	}
	
	class TestThread implements Runnable {
		String threadName;
		
		public TestThread(String threadName) {
			this.threadName = threadName;
		}
		
		@Override
		public void run() {
			try {
    			for (int i=0; i<50000; i++) {
					syncAnimals.add(getRandomAnimal());
    			}
		    } catch(Exception e) {
		        err(e.getClass().getName());
		    }
		}
	}
	
	public void print(Collection<?> c) {
		StringBuilder builder = new StringBuilder();
		Iterator<?> iterator = c.iterator();
		while(iterator.hasNext()) {
			 builder.append(iterator.next())
			        .append(" ");
		}
		log(builder.toString());
	}
	
	@Test
	public void testThread() {
		List<Thread> threads = new ArrayList<>();
		for (int i=0; i<100; i++) {
			threads.add(new Thread(new TestThread("t" + i)));
		}
	    System.out.println("Starting threads");
		for (int i=0; i<100; i++) {
			threads.get(i).start();
		}
	    System.out.println("Waiting for threads");
	    try {
			for (int i=0; i<100; i++) {
				threads.get(i).join();
			}
		} catch (InterruptedException e) {
			e.printStackTrace();
		}
	    
	    System.out.println(buf);
	    assertFalse(failed);
	    
	}


}
